i ran bot 3 4 and 5
all of them ran
until the end
and this is the error i got

(.venv) vishal@LAPTOP-9N92S3AG:/mnt/d/vishals folder/study/code/python/introtoai$ p proj2.py > compete_data_2.log
Exception ignored in: weakref callback  <function TransformNode.set_children.<locals>.<lambda> at 0x000055cbb2f76840>
Traceback (most recent call last):
  File "/mnt/d/vishals folder/study/code/python/introtoai/.venv/lib/pypy3.9/site-packages/matplotlib/transforms.py", line 198, in <lambda>
    self, lambda _, pop=child._parents.pop, k=id_self: pop(k))
KeyError: 94333440778328
Exception ignored in: weakref callback  <function TransformNode.set_children.<locals>.<lambda> at 0x000055cbb5d2a840>
Traceback (most recent call last):
  File "/mnt/d/vishals folder/study/code/python/introtoai/.venv/lib/pypy3.9/site-packages/matplotlib/transforms.py", line 198, in <lambda>
    self, lambda _, pop=child._parents.pop, k=id_self: pop(k))
KeyError: 94333415014488
Exception ignored in: weakref callback  <function TransformNode.set_children.<locals>.<lambda> at 0x000055cbb52200c0>
Traceback (most recent call last):
  File "/mnt/d/vishals folder/study/code/python/introtoai/.venv/lib/pypy3.9/site-packages/matplotlib/transforms.py", line 198, in <lambda>
    self, lambda _, pop=child._parents.pop, k=id_self: pop(k))
KeyError: 94333416947744
Exception ignored in: weakref callback  <function TransformNode.set_children.<locals>.<lambda> at 0x000055cbb51a8520>
Traceback (most recent call last):
  File "/mnt/d/vishals folder/study/code/python/introtoai/.venv/lib/pypy3.9/site-packages/matplotlib/transforms.py", line 198, in <lambda>
    self, lambda _, pop=child._parents.pop, k=id_self: pop(k))
KeyError: 94333386407968
Exception ignored in: weakref callback  <function TransformNode.set_children.<locals>.<lambda> at 0x000055cbb3f50ac0>
Traceback (most recent call last):
  File "/mnt/d/vishals folder/study/code/python/introtoai/.venv/lib/pypy3.9/site-packages/matplotlib/transforms.py", line 198, in <lambda>
    self, lambda _, pop=child._parents.pop, k=id_self: pop(k))
KeyError: 94333405307864
Exception ignored in: weakref callback  <function TransformNode.set_children.<locals>.<lambda> at 0x000055cbb3f50a20>
Traceback (most recent call last):
  File "/mnt/d/vishals folder/study/code/python/introtoai/.venv/lib/pypy3.9/site-packages/matplotlib/transforms.py", line 198, in <lambda>
    self, lambda _, pop=child._parents.pop, k=id_self: pop(k))
KeyError: 94333405308144
Exception ignored in: weakref callback  <function TransformNode.set_children.<locals>.<lambda> at 0x000055cbb84a1060>
Traceback (most recent call last):
  File "/mnt/d/vishals folder/study/code/python/introtoai/.venv/lib/pypy3.9/site-packages/matplotlib/transforms.py", line 198, in <lambda>
    self, lambda _, pop=child._parents.pop, k=id_self: pop(k))
KeyError: 94333386413792
Exception ignored in: weakref callback  <function TransformNode.set_children.<locals>.<lambda> at 0x000055cbb6c5c0c0>
Traceback (most recent call last):
  File "/mnt/d/vishals folder/study/code/python/introtoai/.venv/lib/pypy3.9/site-packages/matplotlib/transforms.py", line 198, in <lambda>
    self, lambda _, pop=child._parents.pop, k=id_self: pop(k))
KeyError: 94333387849760
Exception ignored in: weakref callback  <function TransformNode.set_children.<locals>.<lambda> at 0x000055cbb92f40c0>
Traceback (most recent call last):
  File "/mnt/d/vishals folder/study/code/python/introtoai/.venv/lib/pypy3.9/site-packages/matplotlib/transforms.py", line 198, in <lambda>
    self, lambda _, pop=child._parents.pop, k=id_self: pop(k))
KeyError: 94333433454624


what the fuck is this
i have no fucking clue
good luck dude
i think there's some problem with my matplotlib or something, but let's see
